Workbook
Name \A: #REF!
Name \A: '[1]1.1 INDIC ACC'!#REF!
Name \A: #REF!
Name \A: #REF!
Name \A: #REF!
Name \A: #REF!
Name \A: #REF!
Name \A: #REF!
Name \A: '[1]1.1 INDIC ACC'!#REF!
Name \A: #REF!
Name \A: #REF!
Name \A: '[1]1.1 INDIC ACC'!#REF!
Name \A: #REF!
Name \B: #REF!
Name \B: #REF!
Name \B: #REF!
Name \B: #REF!
Name \B: #REF!
Name \C: #REF!
Name \C: #REF!
Name \C: #REF!
Name \C: #REF!
Name \C: #REF!
Name \D: #REF!
Name \D: #REF!
Name \D: #REF!
Name \D: #REF!
Name \D: #REF!
Name \E: #REF!
Name \E: #REF!
Name \E: #REF!
Name \E: #REF!
Name \E: #REF!
Name \F: #REF!
Name \F: #REF!
Name \F: #REF!
Name \F: #REF!
Name \F: #REF!
Name \G: #REF!
Name \G: #REF!
Name \G: #REF!
Name \G: #REF!
Name \G: #REF!
Name \H: #REF!
Name \H: #REF!
Name \H: #REF!
Name \H: #REF!
Name \H: #REF!
Name \I: #REF!
Name \I: #REF!
Name \I: #REF!
Name \I: #REF!
Name \I: #REF!
Name \J: #REF!
Name \J: #REF!
Name \J: #REF!
Name \J: #REF!
Name \J: #REF!
Name \K: #REF!
Name \K: #REF!

Sheet IMF Tools TOC
A1: Macronia_MASTER_10132015.xlsx
B5: Tab Name | C5: Tab Description | D5: Hidden
B6: Workbook_Flowchart
B7: Solutions
B8: SEFI table
B9: GDP table
B10: GDP_Nominal
B11: LRY
B12: GDP_Real
B13: GDP_Deflator
B14: BOP
B15: IIP
B16: EX_Debt
B17: EX_Stock_Ind
... B53: Fiscal&Monetary (through 2014)

Sheet Soluciones
D1: USE ESTA HOJA PARA LLEVAR UN REGISTRO DE LAS RESPUESTAS QUE INGRESARÁ EN EL PORTAL DEL CURSO EDX.ORG | F1: RESPUESTA | I1: at the beginning of module 3 real sector, start with the initial assumptions listed below
D2: HOJA DE SOLUCIONES DE MACRONIA (Las soluciones numéricas aparecerán en la columna E tan pronto complete sus tareas) | E2: Proyección actual | F2: supuestos de ronda inicial/solución | I2: table (real and nominal) then go through module external sector without doing GDP convergence yet.
I3: file name | J3: main assumptions | K3: tab/cell
B4: Módulo 03 | D4: SECTOR REAL, INFLACIÓN Y DEFLACTOR DEL PIB | E4: 2014 | F4: 2014 | I4: Macronia_baseline phase 1
B5: =B4 -> Módulo 03 | D5: crecimiento del PIB real | E5: ='Cuadro PIB'!J28 -> 4.4517021 | F5: 4.63 | I5: real GDP growth | J5: =E5 -> 4.4517021 | K5: ='Cuadro PIB'!J28
D6: tasa de interés nominal de política monetaria (igual a la del año previo) fijada en la regla de Taylor | E6: ='Regla de Taylor '!E9 -> 9.6716905 | F6: 0.088660415 | H6: exog | I6: nominal policy interest rate | J6: =F6 -> 0.088660415 | K6: ='Taylor Rule '!D8
D7: tasa de interés real de política monetaria (igual a la del año previo) | E7: ='TC nominal'!I40 -> 0.023160213 | F7: 0.027301901 | H7: exog | I7: real policy interest rate | J7: =F7 -> 0.027301901 | K7: ='TC Nominal'!I40
D8: tasa de interés nominal interbancaria (igual a la del año previo) en función de inversión | E8: ='Inversión privada real'!I16 -> 14.671691 | F8: 12.2 | H8: endo | I8: Inflation | J8: =$F$21 -> 7.4814516 | K8: =Inflation!O34
D9: tasa de interés nominal interbancaria (igual a la del año previo) en tasa de interés de sector gob. | E9: =Gob_Stock_Ind!L20 -> 14.671691 | F9: 12.2 | I9: nominal interbank interest rate (set equal to previous year) in Investment function | J9: =F8 -> 12.2 | K9: ='Real private investment'I15
D10: tasa de interés nominal interbancaria (igual a la del año previo) en función de demanda de dinero | E10: =DD!H33 -> 14.671691 | F10: 12.2 | I10: fiscal stimulus (pct of potential output 2013) | J10: 2 | K10: ='Cuadro PIB'!K36
D11: TC nominal (promedio) | E11: ='TC nominal'!I13 -> 563.14785 | F11: 561.46514 | I11: RER gap or Implicit UIP-based RER change (in real terms) (+ depreciation) | J11: ='TC nominal'!I34 -> -0.0031602132 | K11: ='TC Nominal'!I34
D12: índice del tipo de cambio real | E12: ='TC nominal'!H22 -> 99.26981 | F12: 99.26981
B13: =B5 -> Módulo 03 | C13: 3.05 | D13: Pronosticar producto potencial | E13: ='PIB real y brecha del producto'!F14 -> 13178.694 | F13: 13178.694 | I13: memo item:
B14: =B13 -> Módulo 03 | C14: 3.06 | D14: Pronosticar PIB real | E14: ='PIB real y brecha del producto'!G30 -> 13343.319 | F14: 13366.096 | I14: Nominal GDP | J14: ='Cuadro PIB'!L26 -> 26705.763 | K14: ='Cuadro PIB'!L26
B15: =B14 -> Módulo 03 | C15: 3.07 | D15: Pronosticar BRECHA DEL PRODUCTO en porcentaje del producto potencial (porcentaje) | E15: ='PIB real y brecha del producto'!G32 -> 1.2491751 | F15: 1.4220063
B16: =B15 -> Módulo 03 | C16: 3.13 | D16: PRONOSTICAR NIVEL DE CONSUMO REAL (usando proporción del PIB según método simplista) | E16: ='Consumo real privado'!H28 -> 9701.4741 | F16: 9718.0344
B17: =B16 -> Módulo 03 | C17: 3.15 | D17: PRONOSTICAR NIVEL DE DE CONSUMO REAL (usando modelo de corrección de errores del método de regresión y parámetro a corto plazo) | E17: ='Consumo real privado'!H32 -> 9556.7582 | F17: 9567.5224
B18: =B17 -> Módulo 03 | C18: 3.17 | D18: PRONOSTICAR NIVEL DE INVERSIÓN PRIVADA REAL (usando proporción del PIB según método simplista) | E18: ='Inversión privada real'!H30 -> 2440.0991 | F18: 2444.2643
B19: =B18 -> Módulo 03 | C19: 3.2 | D19: PRONOSTICAR NIVEL DE INVERSIÓN PRIVADA REAL (usando método de regresión) y basado en supuesto inicial de tasa de interés | E19: ='Inversión privada real'!H32 -> 2453.5587 | F19: 2538.6693
B20: =B19 -> Módulo 03 | D20: Supuesto de tasa de interés real | E20: ='Inversión privada real'!K16 -> 7.3160213 | F20: 4.7185484
B21: =B20 -> Módulo 03 | C21: 3.25 | D21: PRONOSTICAR INFLACIÓN (con curva de Phillips) | E21: =Inflación!O34 -> 7.3556692 | F21: 7.4814516
B22: =B21 -> Módulo 03 | C22: 3.26 | D22: Usar la ecuación de Phillips para pronosticar la inflación con brecha del producto=2% y brecha del TCR=2,65% | E22: 9.21 | F22: 9.212
B23: =B22 -> Módulo 03 | D23: Supuesto de brecha del TCR (basado en supuesto inicial de tasa de interés real) | E23: =Inflación!K29 -> -0.31525678 | F23: -0.73019014
B24: =B23 -> Módulo 03 | D24: Supuesto: fijar crecimiento inicial de deflactor del PIB igual a la inflación de base | E24: ='Cuadro PIB'!I28 -> 8.1255598 | F24: 7.4814516
B25: =B24 -> Módulo 03 | D25: Dado el deflactor del PIB en 2013 | E25: =Deflactor_PIB!K35 -> 185.1027 | F25: 185.1027
B26: =B25 -> Módulo 03 | C26: 3.28 | D26: Pronosticar PIB nominal inicial (usando fórmula) | E26: ='Cuadro PIB'!L28 -> 26705.763 | F26: 26591.991
B27: =B26 -> Módulo 03 | C27: 3.29 | D27: PIB real | E27: ='PIB real y brecha del producto'!G22 -> 4.4517021 | F27: 4.63
B28: =B27 -> Módulo 03 | D28: Brecha del producto | E28: ='PIB real y brecha del producto'!G32 -> 1.2491751 | F28: 1.4220063
B29: =B28 -> Módulo 03 | D29: Inflación media | E29: =Inflación!O31 -> 7.3556692 | F29: 7.4814516
B31: Módulo 04 | D31: SECTOR EXTERNO | F31: SEMANA 3
B32: Módulo 04 | C32: 4.9 | D32: Pronosticar nivel TCR para 2014 | E32: ='TC nominal'!I22 -> 99.683979 | F32: 99.26981
B33: Módulo 04 | C33: 4.1 | D33: Pronosticar nivel del TC nominal Macronia/USD | E33: ='TC nominal'!I13 -> 563.14785 | F33: 561.46514
B34: Módulo 04 | C34: 4.11 | D34: Pronosticar de variación de TCN para 2014 | E34: ='TC nominal'!I16 -> 6.2104172 | F34: 5.8930557
B35: Módulo 04 | C35: 4.14 | D35: PRONOSTICAR VARIACIÓN DE PRECIO RELATIVO DE IMPORTACIONES | E35: ='Importaciones reales de bienes'!F22 -> 0.41721528 | F35: 0
B36: Módulo 04 | C36: 4.15 | D36: PRONOSTICAR VARIACIÓN DE VOLUMEN DE IMPORTACIONES REALES | E36: ='Importaciones reales de bienes'!O24 -> 5.3384819 | F36: 5.8235001
B37: Módulo 04 | C37: 4.16 | D37: PRONOSTICAR VARIACIÓN DE PRECIO RELATIVO DE EXPORTACIONES | E37: ='Exportaciones reales de bienes'!F23 -> 0.41721528 | F37: 0
B38: Módulo 04 | C38: 4.17 | D38: PRONOSTICAR VARIACIÓN DE VOLUMEN DE EXPORTACIONES REALES | E38: ='Exportaciones reales de bienes'!O25 -> 4.2607596 | F38: 4
B39: Módulo 04 | C39: 4.18 | D39: Pronosticar exportaciones nominales en miles de millones de USD | E39: ='Import. y export. nominales'!M8/1000 -> 12.800176 | F39: 12.768163
B40: Módulo 04 | C40: 4.18 | D40: Pronosticar importaciones nominales en miles de millones de USD | E40: ='Import. y export. nominales'!M10/1000 -> 19.555251 | F40: 19.645291
B41: Módulo 04 | C41: 4.19 | D41: SERVICIOS DE CRÉDITO | E41: =Servicios!I8 -> 6129.8593 | F41: 6114.5284
...

Sheet Cuadro SEFI
C2: Macronia: Indicadores económicos seleccionados, 2008-14
D3: 2008 | E3: =D3+1 -> 2009 | F3: =E3+1 -> 2010 | G3: =F3+1 -> 2011 | H3: =G3+1 -> 2012 | I3: =H3+1 -> 2013 | J3: Base: 2014
D4: (Variación porcentual anual, salvo especificación)
C5: Ingreso nacional y precios
C6: PIB real | D6: 2.4011889 | E6: -1.6305202 | F6: 4.8594958 | G6: 5.6553885 | H6: 4.185179 | I6: 4.557993 | J6: =PIB_real!L23 -> 4.4517021
C7: Brecha del PIB (porcentaje del PIB potencial) | D7: 3.7527713 | E7: -1.579742 | F7: -1.2262808 | G7: -1.3561522 | H7: 0.27332419 | I7: 0.81132237 | J7: =PIB_real!L50 -> 1.2491751
C8: Deflactor del PIB | D8: 11.077943 | E8: 8.6233366 | F8: 6.763734 | G8: 4.3046031 | H8: 4.5272294 | I8: 6.8916443 | J8: =100*(Deflactor_PIB!L35/Deflactor_PIB!K35-1) -> 8.1255598
C9: Índice de precios al consumidor (promedio) | D9: 13.424651 | E9: 7.8427557 | F9: 5.6626532 | G9: 4.8781492 | H9: 4.6130302 | I9: 6.1358513 | J9: =Inflación!R49 -> 7.3556692
C10: Índice de precios al consumidor (fin del período) | D10: 13.900308 | E10: 4.0477107 | F10: 5.8279713 | G10: 4.731288 | H10: 5 | I10: 6.6042632 | J10: =Inflación!R50 -> 7.037935
C11: Tasa de interés real (tasa interbancaria) | D11: -1.9246506 | E11: 0.40724435 | F11: 2.3373468 | G11: 3.1218508 | H11: 4.6369698 | I11: 6.0641487 | J11: ='Inversión privada real'!K16 -> 7.3160213
C13: Sector externo
C14: Exportación de bienes y servicios (variación de volumen) | D14: -3.2262497 | E14: -14.738922 | F14: 4.9130977 | G14: 6.9688892 | H14: 8.5805633 | I14: 3.6726139 | J14: ='Exportaciones reales de bienes'!O25 -> 4.2607596
C15: Exportación de bienes y servicios (variación de precios) | D15: 9.6618891 | E15: 6.9024072 | F15: -0.68224333 | G15: -0.52769458 | H15: 3.3981633 | I15: 1.5 | J15: ='Exportaciones reales de bienes'!F23 -> 0.41721528
C16: Importación de bienes y servicios (variación de volumen) | D16: 4.0192093 | E16: -23.5 | F16: 13.985452 | G16: 12.161374 | H16: 8.7396552 | I16: 4.6261335 | J16: ='Importaciones reales de bienes'!O24 -> 5.3384819
C17: Importación de bienes y servicios (variación de precios) | D17: 12.142037 | E17: -2.4075477 | F17: -5.2576711 | G17: 0.27208527 | H17: 1.5719142 | I17: 1.5 | J17: ='Importaciones reales de bienes'!F22 -> 0.41721528
C18: Términos de intercambio (positivos -) | D18: -2.2116133 | E18: 9.539626 | F18: 4.8293385 | G18: -0.79760967 | H18: 1.7979862 | I18: 0 | J18: =(((1+J15/100)/(1+J17/100))-1)*100 -> 0
C19: Tipo de cambio (MN por USD, promedio) (- apreciación) | D19: 1.8617498 | E19: 8.941328 | F19: -8.2783452 | G19: -3.6949642 | H19: 0.86682713 | I19: 3.8038008 | J19: =100*(BP!L58/BP!K58-1) -> 6.2104172
C20: Tipo de cambio (MN por USD, fin del período) | D20: 11.517768 | E20: 1.7588709 | F20: -9.2473993 | G20: -0.46981305 | H20: 0.089945393 | I20: 7.5143188 | J20: =100*(BP!L59/BP!K59-1) -> 4.9976471
C21: Tipo de cambio real (bilateral MN/USD) (- apreciación) | D21: … | E21: 0.84628357 | F21: -11.877525 | G21: -5.541248 | H21: -1.6935658 | I21: -0.73019014 | J21: =100*('TC nominal'!I22/'TC nominal'!H22-1) -> 0.41721528
D23: (En porcentaje del PIB, salvo indicación en contrario)
C24: Saldo en cuenta corriente | D24: -10.464345 | E24: -1.0412049 | F24: -3.5232025 | G24: -5.766358 | H24: -6.5810767 | I24: -6.653527 | J24: =100*(PIB_Nominal!L26/PIB_Nominal!L6) -> -7.0207629
C25: Del cual: Saldo comercial | D25: -10.394907 | E25: 0.62446844 | F25: -2.4541238 | G25: -4.824109 | H25: -5.1845419 | I25: -5.4825381 | J25: =100*(PIB_Nominal!L14/PIB_Nominal!L6) -> -5.9252434
C26: Saldo en cuenta financiera y de capital | D26: -8.8837946 | E26: -2.6765801 | F26: -5.5293997 | G26: -6.6219847 | H26: -6.5723177 | I26: -6.5879872 | J26: =100*(BP!L21-BP!L19)/BP!L57 -> -6.5050844
C27: Variación de activos de reserva (millones de USD, aumento +) | D27: -314.9 | E27: 267.5 | F27: 563.5 | G27: 128.6 | H27: 49.971609 | I27: -29.228791 | J27: =(PII!L13-PII!K13) -> -244.54656
C28: Activos de reserva (millones de USD) | D28: 3798.7 | E28: 4066.2 | F28: 4629.7 | G28: 4758.3 | H28: 4808.2716 | I28: 4779.0428 | J28: =PII!L13 -> 4534.4963
C29: de los cuales: Financiamiento del FMI (programa) | F29: … | G29: ... | H29: ... | I29: ... | J29: =BP!L44 -> 0
C30: En meses de importaciones (bienes y servicios) | D30: 2.7709037 | E30: 3.9728074 | F30: 3.7694257 | G30: 3.3062959 | H30: 3.0135026 | I30: 2.8204427 | J30: =J28/((BP!L8+BP!L11)/12) -> 2.5029508
C32: Finanzas públicas | D32: (En porcentaje del PIB)
C33: Ingreso | D33: 16.896242 | E33: 15.007707 | F33: 15.486725 | G33: 15.564533 | H33: 15.462876 | I33: 15.332847 | J33: =Gob_EOG_Ind!L6 -> 15.283679
C34: Gasto | D34: 15.899072 | E34: 18.195114 | F34: 20.817859 | G34: 19.614825 | H34: 20.017705 | I34: 23.152225 | J34: =Gob_EOG_Ind!L7 -> 27.711481
C35: del cual Gastos primarios | D35: 13.591401 | E35: 15.908288 | F35: 18.540138 | G35: 17.301764 | H35: 17.78875 | I35: 19.689076 | J35: =Gob_EOG_Ind!L8 -> 22.459537
C36: Saldo primario global | D36: 2.8878592 | E36: -1.434776 | F36: -3.8157089 | G36: -2.5765204 | H36: -3.6374833 | I36: -4.4867053 | J36: =Gob_EOG_Ind!L14 -> -7.2984131
C37: Saldo primario estructural (porcentaje del PIB potencial) | D37: 2.7016741 | E37: -0.61338272 | F37: -2.7973698 | G37: -1.470682 | H37: -2.3808242 | I37: -4.5345448 | J37: =Gob_EOG_Ind!L26 -> -7.4848508
C38: Impulso fiscal (expansivo +) | E38: 3.3150568 | F38: 2.1839871 | G38: -1.3266878 | H38: 0.91014217 | I38: 2.1537206 | J38: =-(J37-I37) -> 2.9503059
C39: Saldo global | D39: 0.58018797 | E39: -3.721602 | F39: -6.0934293 | G39: -4.8895819 | H39: -5.8664381 | I39: -7.9498542 | J39: =Gob_EOG_Ind!L13 -> -12.550357
C40: Deuda del gobierno general | D40: 41.730548 | E40: 42.947517 | F40: 43.945377 | G40: 44.055857 | H40: 44.600625 | I40: 48.102738 | J40: =Gob_Stock_Ind!L7 -> 55.470857
C42: Sector monetario
C43: Dinero en sentido amplio (crecimiento porcentual anual, f.d.p.) | D43: 17.401568 | E43: 8.0332619 | F43: 0.79500651 | G43: 7.3200399 | H43: 9.1 | I43: 9.0006394 | J43: =(MON_PSD!L17-MON_PSD!K17)/MON_PSD!K17*100 -> 8.1977181
C44: Crédito al sector privado (variación porcentual anual) | D44: 31.618642 | E44: 5.299032 | F44: 4.9429232 | G44: 12.392878 | H44: 8.0410539 | I44: 6.8386355 | J44: =(MON_PSD!L13-MON_PSD!K13)/MON_PSD!K13*100 -> 2.9443063
C45: Velocidad (PIB/promedio dinero en sentido amplio) | D45: 1.8087583 | E45: 1.7203628 | F45: 1.84703 | G45: 1.9558777 | H45: 1.9678115 | I45: 2.0168154 | J45: =MON_IND!L27 -> 2.0977448
...

Sheet Cuadro PIB
C2: Macronia: PIB, coherencia de precios y volúmenes, 2014
C3: Pronóstico de base
D4: 2013 | G4: 2014
D5: Valor (miles de millones de MN) | H5: % Δ precio | J5: % Δ | K5: Valor (miles de millones de MN) | M5: proporción %
D6: a precios de '05 | E6: a precios de '13 | G6: USD | H6: MN/USD | I6: MN | J6: volumen | K6: a precios de '05 | L6: a precios de '14 | M6: del PIB
D7: [I] | E7: [II] | G7: [III] | H7: [IV] | I7: [V]= III*IV | J7: [VI] | K7: [VII]= I*VI | L7: [VIII]= VII*V | M7: [IX]
C10: Consumo | D10: =PIB_real!K7 -> 10605.631 | E10: =PIB_Nominal!K7 -> 19985.487 | G10: . . . | H10: . . . | I10: =(L10/E10/(1+J10%)-1)*100 -> 8.1038324 | J10: =(K10/D10-1)*100 -> 5.0193341 | K10: =K11+K12 -> 11137.963 | L10: =L11+L12 -> 22689.509 | M10: =L10/L$26*100 -> 84.961094
C11: Privado | D11: =PIB_real!K8 -> 9288 | E11: =PIB_Nominal!K8 -> 16647.635 | G11: . . . | H11: . . . | I11: =Inflación!O31 -> 7.3556692 | J11: ='Consumo real privado'!J34 -> 2.8936064 | K11: =D11*(1+J11/100) -> 9556.7582 | L11: =E11*(1+I11/100)*(1+J11/100) -> 18389.33 | M11: =L11/L$26*100 -> 68.859033
C12: Público | D12: =PIB_real!K9 -> 1317.6308 | E12: =PIB_Nominal!K9 -> 3337.8524 | G12: . . . | H12: . . . | I12: =(L12/E12/(1+J12%)-1)*100 -> 7.3556692 | J12: =100*(K12/D12-1) -> 20.003622 | K12: =D12+(K36*K32) -> 1581.2047 | L12: =L13+L14 -> 4300.1784 | M12: =L12/L$26*100 -> 16.102061
C13: Gobierno general | D13: . . . | E13: =Gob_EOG!K16+Gob_EOG!K17 -> 2169.1777 | I13: =I11 -> 7.3556692 | J13: =J12 -> 20.003622 | K13: . . . | L13: =E13*(1+I13/100)*(1+J13/100) -> 2794.5667 | M13: =L13/L$26*100 -> 10.464283
C14: Resto del sector público | D14: . . . | E14: =E12-E13 -> 1168.6747 | G14: . . . | H14: . . . | I14: =I13 -> 7.3556692 | J14: =J12 -> 20.003622 | K14: . . . | L14: =E14*(1+I14/100)*(1+J14/100) -> 1505.6117 | M14: =L14/L$26*100 -> 5.6377782
C15: Inversión | D15: =PIB_real!K10 -> 2941 | E15: =PIB_Nominal!K10 -> 4957.11 | G15: . . . | H15: . . . | I15: =(L15/E15/(1+J15%)-1)*100 -> 7.5348309 | J15: =((K15/D15)-1)*100 -> 5.0278602 | K15: =(K18+K17+K16) -> 3088.8694 | L15: =(L18+L17+L16) -> 5598.6359 | M15: =L15/L$26*100 -> 20.964149
C16: Privado | D16: =PIB_real!K11 -> 2336.1027 | E16: =PIB_Nominal!K11 -> 4062.9269 | G16: . . . | H16: . . . | I16: =0.6*I11+0.4*I22 -> 7.5348309 | J16: ='Inversión privada real'!J36 -> 5.0278602 | K16: =D16*(1+J16/100) -> 2453.5587 | L16: =E16*(1+I16/100)*(1+J16/100) -> 4588.7319 | M16: =L16/L$26*100 -> 17.182553
C17: Público | D17: =PIB_real!K12 -> 339.92761 | E17: =PIB_Nominal!K12 -> 590.02673 | G17: . . . | H17: . . . | I17: =0.6*I11+0.4*I22 -> 7.5348309 | J17: =J16 -> 5.0278602 | K17: =D17*(1+J17/100) -> 357.0187 | L17: =E17*(1+I17/100)*(1+J17/100) -> 666.38523 | M17: =L17/L$26*100 -> 2.4952862
C18: =PIB_Nominal!C13 -> Variación de saldos | D18: =PIB_real!K13 -> 264.96964 | E18: =PIB_Nominal!K13 -> 304.15633 | G18: . . . | H18: . . . | I18: =0.6*I11+0.4*I22 -> 7.5348309 | J18: =J17 -> 5.0278602 | K18: =D18*(1+J18/100) -> 278.29195 | L18: =E18*(1+I18/100)*(1+J18/100) -> 343.51882 | M18: =L18/L$26*100 -> 1.2863097
C20: =PIB_Nominal!C15 -> Exportaciones de bienes y servicios | D20: =PIB_real!K15 -> 6523 | E20: =PIB_Nominal!K15 -> 9484.6174 | G20: ='Exportaciones reales de bienes'!F17 -> 1.5 | H20: ='TC nominal'!I16 -> 6.2104172 | I20: =((1+G20/100)*(1+H20/100)-1)*100 -> 7.8035735 | J20: ='Exportaciones reales de bienes'!O25 -> 4.2607596 | K20: =D20*(1+J20/100) -> 6800.9293 | L20: =E20*(1+I20/100)*(1+J20/100) -> 10660.409 | M20: =L20/L$26*100 -> 39.918008
C22: =PIB_Nominal!C16 -> Importaciones de bienes y servicios | D22: =PIB_real!K16 -> 7295 | E22: =PIB_Nominal!K16 -> 10781.029 | G22: ='Importaciones reales de bienes'!F16 -> 1.5 | H22: =H20 -> 6.2104172 | I22: =((1+G22/100)*(1+H22/100)-1)*100 -> 7.8035735 | J22: ='Importaciones reales de bienes'!O24 -> 5.3384819 | K22: =D22*(1+J22/100) -> 7684.4423 | L22: =E22*(1+I22/100)*(1+J22/100) -> 12242.79 | M22: =L22/L$26*100 -> 45.843252
C24: Discrepancia estadística | D24: =PIB_real!K17 -> 0 | E24: =PIB_Nominal!K17 -> 0 | G24: . . . | H24: . . . | I24: =I28 -> 8.1255598 | J24: -100 | K24: =D24*(1+J24/100) -> 0 | L24: =K24*(1+I24/100) -> 0 | M24: =L24/L$26*100 -> 0
C26: PIB-suma de gastos | D26: =D10+D15+D20-D22+D24 -> 12774.631 | E26: =E10+E15+E20-E22+E24 -> 23646.186 | G26: . . . | H26: . . . | I26: =(L26/E26/(1+J26/100)-1)*100 -> 8.1255598 | J26: =((K26/D26)-1)*100 -> 4.4517021 | K26: =K10+K15+K20-K22+K24 -> 13343.319 | L26: =L10+L15+L20-L22+L24 -> 26705.763 | M26: 100
C28: PIB-proyección inicial | G28: . . . | H28: . . . | I28: 8.1255598 | J28: 4.4517021 | K28: =D26*(1+J28/100) -> 13343.319 | L28: =E26*(1+I28/100)*(1+J28/100) -> 26705.763 | P28: Note: | Y28: Cell I28 | Z28: Cell J28
C29: verificación | K29: =K26-K28 -> 0 | L29: =L26-L28 -> 0 | P29: - Until Module 5, your cells I28 and J28 will use the initial assumptions. | X29: Initial | Y29: 7.48 | Z29: 4.63
P30: - In Module 5, you will revise them to reflect the expenditure approach estimation. | X30: Revised | Y30: 9.2087336 | Z30: 5.305556
C31: Partida informativa:
C32: Producto potencial (precios de 2005) | D32: =PIB_real!K19 -> 12671.821 | K32: =PIB_real!L19 -> 13178.694
C33: Demanda interna | D33: =D10+D15 -> 13546.631 | E33: =D33/D$26*100 -> 106.04323 | K33: =K10+K15 -> 14226.832 | L33: =L10+L15 -> 28288.144 | M33: =M10+M15 -> 105.92524
C34: Exportaciones netas | D34: =D20-D22 -> -772 | E34: =D34/D$26*100 -> -6.0432275 | K34: =K20-K22 -> -883.51291 | L34: =L20-L22 -> -1582.3815 | M34: =L34/L$26*100 -> -5.9252434
C36: Estímulo fiscal (en porcentaje del producto potencial, respecto a 2013) | K36: 0.02
C37: Proyección de brecha del tipo de cambio real pestaña TC nominal (verificar que sea igual a lo siguiente) | K37: ='TC nominal'!I34*100 -> -0.31602132
C38: Proyección de brecha del tipo de cambio real pestaña Inflación | K38: =Inflación!K29 -> -0.31525678
C39: Endeudamiento interno (verificar=0 de Hoja Gob_exp_proy) | K39: ='Hoja-Gob_Exp_Proy.'!I41 -> -4.0927262e-12
C42: NOTA
C43: Nivel deflactor 2013
C44: Deflactor del consumo (privado) | D44: =E11/D11 -> 1.792381
C45: Deflactor del consumo (público) | D45: =E12/D12 -> 2.5332228

Sheet PIB_Nominal
B2: Macronia: PIB nominal, 2006-14
D3: 2006 | E3: 2007 | F3: 2008 | G3: 2009 | H3: 2010 | I3: 2011 | J3: 2012 | K3: 2013 | L3: 2014
B4: (en miles de millones de moneda nacional)
C5: Producto interno bruto, a precios corrientes
C6: PIB | D6: 10964.62 | E6: 12956.322 | F6: 14737.186 | G6: 15747.009 | H6: 17629.078 | I6: 19427.849 | J6: 21157.293 | K6: 23646.186 | L6: ='Cuadro PIB'!L26 -> 26705.763
C7: Consumo final | D7: 8700.4437 | E7: 10352.871 | F7: 12200.565 | G7: 13108.591 | H7: 14576.657 | I7: 16016.788 | J7: 17760.343 | K7: 19985.487 | L7: =L8+L9 -> 22689.509
C8: Privado | D8: 7624.2096 | E8: 9087.1639 | F8: 10645.097 | G8: 11176.638 | H8: 12277.757 | I8: 13520.438 | J8: 15027.228 | K8: 16647.635 | L8: ='Cuadro PIB'!L11 -> 18389.33
C9: Público | D9: 1076.2341 | E9: 1265.7069 | F9: 1555.4684 | G9: 1931.9535 | H9: 2298.9 | I9: 2496.35 | J9: 2733.1145 | K9: 3337.8524 | L9: ='Cuadro PIB'!L12 -> 4300.1784
C10: Formación bruta de capital fijo | D10: 2919.2115 | E10: 3202.1678 | F10: 4044.0793 | G10: 2463.1898 | H10: 3463.1683 | I10: 4287.2834 | J10: 4493.8592 | K10: 4957.11 | L10: =L11+L12+L13 -> 5598.6359
C11: Privada | D11: 1935.5708 | E11: 2523.1836 | F11: 3083.0458 | G11: 3105.0591 | H11: 2992.8914 | I11: 3513.9263 | J11: 3683.2391 | K11: 4062.9269 | L11: ='Cuadro PIB'!L16 -> 4588.7319
C12: Pública | D12: 234.02446 | E12: 286.08395 | F12: 335.24812 | G12: 328.85775 | H12: 425.53619 | I12: 510.29972 | J12: 534.88768 | K12: 590.02673 | L12: ='Cuadro PIB'!L17 -> 666.38523
C13: Variación de saldos | D13: 749.61619 | E13: 392.90029 | F13: 625.78538 | G13: -970.72705 | H13: 44.740729 | I13: 263.05738 | J13: 275.73238 | K13: 304.15633 | L13: ='Cuadro PIB'!L18 -> 343.51882
C14: Saldo externo | D14: -708.14401 | E14: -653.40526 | F14: -1531.9167 | G14: 98.335101 | H14: -432.6394 | I14: -937.22061 | J14: -1096.9087 | K14: -1296.4112 | L14: =+L15-L16 -> -1582.3815
C15: Exportaciones de bienes y servicios | D15: 5658.5976 | E15: 6623.9268 | F15: 7134.1258 | G15: 7122.0184 | H15: 7248.1128 | I15: 7780.1097 | J15: 8683.1333 | K15: 9484.6174 | L15: ='Cuadro PIB'!L20 -> 10660.409
C16: Importaciones de bienes y servicios | D16: 6366.7416 | E16: 7277.3321 | F16: 8666.0425 | G16: 7023.6833 | H16: 7680.7522 | I16: 8717.3303 | J16: 9780.042 | K16: 10781.029 | L16: ='Cuadro PIB'!L22 -> 12242.79
C17: Discrepancia estadística | D17: 53.108978 | E17: 54.688654 | F17: 24.458182 | G17: 76.893057 | H17: 21.891565 | I17: 60.998131 | J17: 0 | K17: 0 | L17: =L6-L7-L10-L14 -> 0
C19: Ingreso nacional, absorción, ahorro y saldo ahorro-inversión
C20: Ingreso nacional bruto | D20: 10926.691 | E20: 12650.86 | F20: 14469.74 | G20: 15202.127 | H20: 17226.001 | I20: 19020.276 | J20: 20691.475 | K20: 23187.478 | L20: =L6+L40 -> 26214.646
C21: Ingreso nacional bruto disponible | D21: 11105.187 | E21: 12893.516 | F21: 14702.494 | G21: 15407.822 | H21: 17418.718 | I21: 19183.792 | J21: 20861.824 | K21: 23369.292 | L21: =L6+L40+L41 -> 26413.196
C22: Absorción | D22: 11619.655 | E22: 13555.039 | F22: 16244.644 | G22: 15571.781 | H22: 18039.826 | I22: 20304.072 | J22: 22254.202 | K22: 24942.597 | L22: =L7+L10 -> 28288.144
C23: Ahorro nacional | D23: 2404.7433 | E23: 2540.6447 | F23: 2501.9293 | G23: 2299.2311 | H23: 2842.0602 | I23: 3167.0041 | J23: 3101.4815 | K23: 3383.8046 | L23: =L21-L7 -> 3723.6876
C24: Inversión | D24: 2919.2115 | E24: 3202.1678 | F24: 4044.0793 | G24: 2463.1898 | H24: 3463.1683 | I24: 4287.2834 | J24: 4493.8592 | K24: 4957.11 | L24: =L10 -> 5598.6359
C25: Saldo ahorro-inversión | D25: -514.46823 | E25: -661.52313 | F25: -1542.15 | G25: -163.95864 | H25: -621.10812 | I25: -1120.2793 | J25: -1392.3777 | K25: -1573.3054 | L25: =L23-L24 -> -1874.9483
C26: Saldo en cuenta corriente (miles de millones MN) | D26: -514.46823 | E26: -661.52313 | F26: -1542.15 | G26: -163.95864 | H26: -621.10812 | I26: -1120.2793 | J26: -1392.3777 | K26: -1573.3054 | L26: =L14+L40+L41 -> -1874.9483
B27: (en porcentaje del PIB)
C28: Indicadores económicos seleccionados
C29: Absorción | D29: 105.97408 | E29: 104.62104 | F29: 110.22894 | G29: 98.887229 | H29: 102.32995 | I29: 104.51014 | J29: 105.18454 | K29: 105.48254 | L29: =L22/L6*100 -> 105.92524
C30: Consumo final | D30: 79.350161 | E30: 79.905939 | F30: 82.787618 | G30: 83.244958 | H30: 82.685308 | I30: 82.442416 | J30: 83.944305 | K30: 84.518861 | L30: =L7/L6*100 -> 84.961094
C31: Formación bruta de capital fijo | D31: 26.623918 | E31: 24.715099 | F31: 27.441326 | G31: 15.642271 | H31: 19.644637 | I31: 22.06772 | J31: 21.240237 | K31: 20.963677 | L31: =L10/L6*100 -> 20.964149
C32: Exportaciones de bienes y servicios | D32: 51.607785 | E32: 51.125055 | F32: 48.40901 | G32: 45.227753 | H32: 41.114532 | I32: 40.046171 | J32: 41.040852 | K32: 40.110559 | L32: =L15/L6*100 -> 39.918008
C33: Importaciones de bienes y servicios | D33: 58.06623 | E33: 56.168194 | F33: 58.803916 | G33: 44.603285 | H33: 43.568655 | I33: 44.87028 | J33: 46.225393 | K33: 45.593097 | L33: =L16/L6*100 -> 45.843252
C34: Ahorro nacional | D34: 21.931843 | E34: 19.609305 | F34: 16.976981 | G34: 14.601066 | H34: 16.121434 | I34: 16.301362 | J34: 14.65916 | K34: 14.31015 | L34: =L23/L6*100 -> 13.943386
C35: Inversión | D35: 26.623918 | E35: 24.715099 | F35: 27.441326 | G35: 15.642271 | H35: 19.644637 | I35: 22.06772 | J35: 21.240237 | K35: 20.963677 | L35: =L10/L6*100 -> 20.964149
C36: Saldo ahorro-inversión | D36: -4.6920752 | E36: -5.1057941 | F36: -10.464345 | G36: -1.0412049 | H36: -3.5232025 | I36: -5.766358 | J36: -6.5810767 | K36: -6.653527 | L36: =L25/L6*100 -> -7.0207629
B38: (en miles de millones de moneda nacional)
C39: Otras partidas, de la balanza de pagos
C40: Saldo de ingreso primario | D40: -37.928659 | E40: -305.46171 | F40: -267.44546 | G40: -544.88251 | H40: -403.07669 | I40: -407.57341 | J40: -465.8177 | K40: -458.70834 | L40: =BP!L12*BP!L58/1000 -> -491.117
C41: Saldo de ingreso secundario | D41: 178.49546 | E41: 242.65519 | F41: 232.75397 | G41: 205.69572 | H41: 192.7164 | I41: 163.51656 | J41: 170.34874 | K41: 181.81414 | L41: =BP!L17*'TC nominal'!I13/1000 -> 198.55017

Sheet LRY
B1: PRODUCTO RESUMIDO
B3: Estadísticas de la regresión
B4: R múltiple | C4: 0.99405164
B5: R cuadrado | C5: 0.98813867
B6: R cuadrado ajustado | C6: 0.98784937
B7: Error estándar | C7: 0.05600592
B8: Observaciones | C8: 43
B10: ANOVA
C11: df | D11: SS | E11: MS | F11: F | G11: Significancia F
B12: Regresión | C12: 1 | D12: 10.713619 | E12: 10.713619 | F12: 3415.6103 | G12: 4.1219775e-41
B13: Residuo | C13: 41 | D13: 0.12860319 | E13: 0.0031366631
B14: Total | C14: 42 | D14: 10.842222
C16: Coeficiente | D16: Error estándar | E16: Estadística t | F16: Valor P | G16: 95% inferior | H16: 95% superior | I16: 95,0% inferior | J16: 95,0% superior
B17: Ordenada en el origen | C17: 7.6744177 | D17: 0.017383999 | E17: 441.46446 | F17: 5.1572067e-77 | G17: 7.63931 | H17: 7.7095254 | I17: 7.63931 | J17: 7.7095254
B18: X Variable 1 | C18: 0.040222912 | D18: 0.00068823911 | E18: 58.443223 | F18: 4.1219775e-41 | G18: 0.038832985 | H18: 0.041612839 | I18: 0.038832985 | J18: 0.041612839
B20: Notación:
B21: RY | C21: PIB real
B22: ln RY | C22: Logaritmo natural del PIB real
B23: Tiempo | C23: Tendencia de tiempo
C24: RY | D24: LRY | E24: Tendencia de tiempo
C25: PIB real efectivo | D25: Log o PIB real | E25: Tendencia de tiempo | F25: Ajustado | G25: Observación | H25: LRY predicha | I25: Residuos | J25: serie original | K25: verificación
B26: 1970 | C26: 2113.5785 | D26: =LN(C26) -> 7.6561378 | E26: 1 | F26: =$C$17+$C$18*G26 -> 7.7146406 | G26: 1 | H26: 7.7146406 | I26: -0.058502881 | J26: =F26+I26 -> 7.6561378 | K26: =J26-D26 -> 0
B27: =B26+1 -> 1971 | C27: 2256.8475 | D27: =LN(C27) -> 7.7217242 | E27: =E26+1 -> 2 | F27: =$C$17+$C$18*G27 -> 7.7548636 | G27: 2 | H27: 7.7548636 | I27: -0.033139333 | J27: =F27+I27 -> 7.7217242 | K27: =J27-D27 -> 0
B28: =B27+1 -> 1972 | C28: 2441.4135 | D28: =LN(C28) -> 7.8003325 | E28: =E27+1 -> 3 | F28: =$C$17+$C$18*G28 -> 7.7950865 | G28: 3 | H28: 7.7950865 | I28: 0.0052460053 | J28: =F28+I28 -> 7.8003325 | K28: =J28-D28 -> 0
B29: =B28+1 -> 1973 | C29: 2629.6201 | D29: =LN(C29) -> 7.8745946 | E29: =E28+1 -> 4 | F29: =$C$17+$C$18*G29 -> 7.8353094 | G29: 4 | H29: 7.8353094 | I29: 0.039285272 | J29: =F29+I29 -> 7.8745946 | K29: =J29-D29 -> 0
B30: =B29+1 -> 1974 | C30: 2775.4299 | D30: =LN(C30) -> 7.9285609 | E30: =E29+1 -> 5 | F30: =$C$17+$C$18*G30 -> 7.8755323 | G30: 5 | H30: 7.8755323 | I30: 0.053028629 | J30: =F30+I30 -> 7.9285609 | K30: =J30-D30 -> 0
B31: =B30+1 -> 1975 | C31: 2833.7159 | D31: =LN(C31) -> 7.9493442 | E31: =E30+1 -> 6 | F31: =$C$17+$C$18*G31 -> 7.9157552 | G31: 6 | H31: 7.9157552 | I31: 0.033588952 | J31: =F31+I31 -> 7.9493442 | K31: =J31-D31 -> 0
B32: =B31+1 -> 1976 | C32: 2990.068 | D32: =LN(C32) -> 8.0030514 | E32: =E31+1 -> 7 | F32: =$C$17+$C$18*G32 -> 7.9559781 | G32: 7 | H32: 7.9559781 | I32: 0.047073281 | J32: =F32+I32 -> 8.0030514 | K32: =J32-D32 -> 0
B33: =B32+1 -> 1977 | C33: 3256.3178 | D33: =LN(C33) -> 8.0883523 | E33: =E32+1 -> 8 | F33: =$C$17+$C$18*G33 -> 7.996201 | G33: 8 | H33: 7.996201 | I33: 0.092151299 | J33: =F33+I33 -> 8.0883523 | K33: =J33-D33 -> 0
B34: =B33+1 -> 1978 | C34: 3460.4136 | D34: =LN(C34) -> 8.1491434 | E34: =E33+1 -> 9 | F34: =$C$17+$C$18*G34 -> 8.0364239 | G34: 9 | H34: 8.0364239 | I34: 0.11271946 | J34: =F34+I34 -> 8.1491434 | K34: =J34-D34 -> 0
B35: =B34+1 -> 1979 | C35: 3631.4035 | D35: =LN(C35) -> 8.1973745 | E35: =E34+1 -> 10 | F35: =$C$17+$C$18*G35 -> 8.0766468 | G35: 10 | H35: 8.0766468 | I35: 0.12072766 | J35: =F35+I35 -> 8.1973745 | K35: =J35-D35 -> 0
B36: =B35+1 -> 1980 | C36: 3658.7073 | D36: =LN(C36) -> 8.2048652 | E36: =E35+1 -> 11 | F36: =$C$17+$C$18*G36 -> 8.1168698 | G36: 11 | H36: 8.1168698 | I36: 0.087995417 | J36: =F36+I36 -> 8.2048652 | K36: =J36-D36 -> 0
B37: =B36+1 -> 1981 | C37: 3575.879 | D37: =LN(C37) -> 8.1819663 | E37: =E36+1 -> 12 | F37: =$C$17+$C$18*G37 -> 8.1570927 | G37: 12 | H37: 8.1570927 | I37: 0.024873635 | J37: =F37+I37 -> 8.1819663 | K37: =J37-D37 -> 0
B38: =B37+1 -> 1982 | C38: 3315.3264 | D38: =LN(C38) -> 8.1063114 | E38: =E37+1 -> 13 | F38: =$C$17+$C$18*G38 -> 8.1973156 | G38: 13 | H38: 8.1973156 | I38: -0.091004222 | J38: =F38+I38 -> 8.1063114 | K38: =J38-D38 -> 0
B39: =B38+1 -> 1983 | C39: 3453.1153 | D39: =LN(C39) -> 8.1470321 | E39: =E38+1 -> 14 | F39: =$C$17+$C$18*G39 -> 8.2375385 | G39: 14 | H39: 8.2375385 | I39: -0.090506407 | J39: =F39+I39 -> 8.1470321 | K39: =J39-D39 -> 0
B40: =B39+1 -> 1984 | C40: 3730.3475 | D40: =LN(C40) -> 8.2242567 | E40: =E39+1 -> 15 | F40: =$C$17+$C$18*G40 -> 8.2777614 | G40: 15 | H40: 8.2777614 | I40: -0.053504733 | J40: =F40+I40 -> 8.2242567 | K40: =J40-D40 -> 0 | M40: results from Eviews
B41: =B40+1 -> 1985 | C41: 3757.2658 | D41: =LN(C41) -> 8.2314468 | E41: =E40+1 -> 16 | F41: =$C$17+$C$18*G41 -> 8.3179843 | G41: 16 | H41: 8.3179843 | I41: -0.086537539 | J41: =F41+I41 -> 8.2314468 | K41: =J41-D41 -> 0
B42: =B41+1 -> 1986 | C42: 3965.2774 | D42: =LN(C42) -> 8.2853311 | E42: =E41+1 -> 17 | F42: =$C$17+$C$18*G42 -> 8.3582072 | G42: 17 | H42: 8.3582072 | I42: -0.072876133 | J42: =F42+I42 -> 8.2853311 | K42: =J42-D42 -> 0
B43: =B42+1 -> 1987 | C43: 4154.2044 | D43: =LN(C43) -> 8.3318762 | E43: =E42+1 -> 18 | F43: =$C$17+$C$18*G43 -> 8.3984301 | G43: 18 | H43: 8.3984301 | I43: -0.066553939 | J43: =F43+I43 -> 8.3318762 | K43: =J43-D43 -> 0
B44: =B43+1 -> 1988 | C44: 4296.7828 | D44: =LN(C44) -> 8.3656218 | E44: =E43+1 -> 19 | F44: =$C$17+$C$18*G44 -> 8.4386531 | G44: 19 | H44: 8.4386531 | I44: -0.07303122 | J44: =F44+I44 -> 8.3656218 | K44: =J44-D44 -> 0
...

Sheet PIB_real
B2: Macronia: PIB real y crecimiento, 2008-14
D3: 2006 | E3: 2007 | F3: 2008 | G3: 2009 | H3: 2010 | I3: 2011 | J3: 2012 | K3: 2013 | L3: =+K3+1 -> 2014
B4: (en miles de millones de moneda nacional)
C5: Producto interno bruto por gasto, a precios constantes de 2005
C6: PIB | D6: 9864.103 | E6: 10508.008 | F6: 10760.325 | G6: 10584.876 | H6: 11099.247 | I6: 11726.953 | J6: 12217.747 | K6: 12774.631 | L6: =L7+L10+L14+L17 -> 13343.319
C7: Consumo final | D7: 7726.1683 | E7: 8269.9833 | F7: 8549.1915 | G7: 8737.0493 | H7: 9135.1104 | I7: 9504.6399 | J7: 10043.482 | K7: 10605.631 | L7: =L8+L9 -> 11137.963
C8: Privado | D8: 6791.1229 | E8: 7301.5719 | F8: 7553.2801 | G8: 7682.1636 | H8: 8033.693 | I8: 8406.4347 | J8: 8898.374 | K8: 9288 | L8: =K8*(1+L25/100) -> 9556.7582
C9: Público | D9: 935.04534 | E9: 968.41137 | F9: 995.91147 | G9: 1054.8857 | H9: 1101.4174 | I9: 1098.2052 | J9: 1145.1083 | K9: 1317.6308 | L9: =K9*(1+L26/100) -> 1581.2047
C10: Formación bruta de capital fijo | D10: 2553.3827 | E10: 2388.8262 | F10: 2881.415 | G10: 1647.7264 | H10: 2250.0575 | I10: 2803.1322 | J10: 2821.4848 | K10: 2941 | L10: =L11+L12+L13 -> 3088.8694
C11: Privada | D11: 1667.8795 | E11: 1987.7598 | F11: 2155.8517 | G11: 1924.3946 | H11: 1897.3962 | I11: 2226.5912 | J11: 2241.1691 | K11: 2336.1027 | L11: =K11*(1+L28/100) -> 2453.5587
C12: Pública | D12: 202.05922 | E12: 225.82414 | F12: 234.89139 | G12: 204.21807 | H12: 270.31204 | I12: 323.99253 | J12: 326.11377 | K12: 339.92761 | L12: =K12*(1+L29/100) -> 357.0187
C13: Variación de saldos | D13: 683.44407 | E13: 175.24233 | F13: 490.6719 | G13: -480.8862 | H13: 82.349342 | I13: 252.54843 | J13: 254.20191 | K13: 264.96964 | L13: =K13*(1+L30/100) -> 278.29195
C14: Saldo externo | D14: -463.29412 | E14: -195.84423 | F14: -688.20384 | G14: 148.11167 | H14: -299.6251 | I14: -617.35019 | J14: -680.52337 | K14: -772 | L14: =+L15-L16 -> -883.51291
C15: Exportaciones de bienes y servicios | D15: 5101.933 | E15: 5607.2954 | F15: 5494.3211 | G15: 5163.4984 | H15: 5417.1861 | I15: 5794.7038 | J15: 6291.922 | K15: 6523 | L15: =+K15*(1+L32/100) -> 6800.9293
C16: Importaciones de bienes y servicios | D16: 5565.2271 | E16: 5803.1396 | F16: 6182.525 | G16: 5015.3867 | H16: 5716.8112 | I16: 6412.054 | J16: 6972.4454 | K16: 7295 | L16: =+K16*(1+L33/100) -> 7684.4423
C17: Discrepancia estadística | D17: 47.846148 | E17: 45.04249 | F17: 17.922271 | G17: 51.988291 | H17: 13.704398 | I17: 36.53094 | J17: 33.303032 | K17: 0 | L17: =+K17*(1+L34/100) -> 0
C19: Producto potencial | D19: 9649.9079 | E19: 9961.0923 | F19: 10371.121 | G19: 10754.773 | H19: 11237.045 | I19: 11888.175 | J19: 12184.444 | K19: 12671.821 | L19: ='PIB real y brecha del producto'!F14 -> 13178.694
C22: Tasas de crecimiento
C23: PIB | D23: 8.8431346 | E23: 6.5277581 | F23: 2.4011889 | G23: -1.6305202 | H23: 4.8594958 | I23: 5.6553885 | J23: 4.185179 | K23: 4.557993 | L23: =(L6/K6-1)*100 -> 4.4517021
C24: Consumo final | D24: 5.4417978 | E24: 7.0386127 | F24: 3.3761643 | G24: 2.1973742 | H24: 4.5560134 | I24: 4.0451562 | J24: 5.6692565 | K24: 5.5971473 | L24: =(L7/K7-1)*100 -> 5.0193341
C25: Privado | D25: 5.7411312 | E25: 7.5164157 | F25: 3.4473142 | G25: 1.7063254 | H25: 4.575916 | I25: 4.6397309 | J25: 5.851938 | K25: 4.3786197 | L25: ='Cuadro PIB'!J11 -> 2.8936064
C26: Público | D26: 3.3176026 | E26: 3.5683867 | F26: 2.8397127 | G26: 5.92163 | H26: 4.4110735 | I26: -0.29164671 | J26: 4.2708835 | K26: 15.066047 | L26: ='Cuadro PIB'!J12 -> 20.003622
C27: Formación bruta de capital fijo | D27: 15.027749 | E27: -6.444647 | F27: 20.620534 | G27: -42.815372 | H27: 36.555287 | I27: 24.580465 | J27: 0.65471915 | K27: 4.2358972 | L27: =(L10/K10-1)*100 -> 5.0278602
C28: Privada | D28: 11.557973 | E28: 19.178863 | F28: 8.4563498 | G28: -10.736227 | H28: -1.4029552 | I28: 17.349832 | J28: 0.65471915 | K28: 4.2358972 | L28: ='Cuadro PIB'!J16 -> 5.0278602
C29: Pública | D29: 6.6221782 | E29: 11.761366 | F29: 4.015179 | G29: -13.058512 | H29: 32.36441 | I29: 19.858711 | J29: 0.65471915 | K29: 4.2358972 | L29: ='Cuadro PIB'!J17 -> 5.0278602
C30: Variación de saldos | D30: 27.696678 | E30: -74.358936 | F30: 179.99622 | G30: -198.00565 | H30: -117.1245 | I30: 206.67935 | J30: 0.65471915 | K30: 4.2358972 | L30: ='Cuadro PIB'!J18 -> 5.0278602
C31: Saldo externo | D31: … | E31: ... | F31: ... | G31: ... | H31: ... | I31: ... | J31: ... | K31: ... | L31: ...
C32: Exportaciones de bienes y servicios | D32: 10.278473 | E32: 9.9053129 | F32: -2.0147725 | G32: -6.0211766 | H32: 4.9130977 | I32: 6.9688892 | J32: 8.5805633 | K32: 3.6726139 | L32: ='Cuadro PIB'!J20 -> 4.2607596
C33: Importaciones de bienes y servicios | D33: 8.0920212 | E33: 4.2749835 | F33: 6.5375881 | G33: -18.87802 | H33: 13.985452 | I33: 12.161374 | J33: 8.7396552 | K33: 4.6261335 | L33: ='Cuadro PIB'!J22 -> 5.3384819
C34: Discrepancia estadística | D34: … | E34: ... | F34: -60.210301 | G34: 190.07647 | H34: -73.639452 | I34: 166.56362 | J34: -8.8360914 | K34: -100 | L34: ='Cuadro PIB'!J24 -> -100
C36: Producto potencial | D36: 4.7601995 | E36: 3.2247387 | F36: 4.1162981 | G36: 3.6992418 | H36: 4.4842567 | I36: 5.7944911 | J36: 2.4921336 | K36: 4 | L36: =L19/K19*100-100 -> 4
C39: Contribución al crecimiento del PIB
C40: Consumo final | D40: … | E40: 5.5130716 | F40: 2.6570995 | G40: 1.745837 | H40: 3.7606595 | I40: 3.3293202 | J40: 4.5949056 | K40: 4.6010816 | L40: =(L7-K7)/K6*100 -> 4.1671032
C41: Consumo privado | E41: 5.1748145 | F41: 2.3953934 | G41: 1.1977662 | H41: 3.3210532 | I41: 3.3582614 | J41: 4.1949461 | K41: 3.1890165 | L41: =(L8-K8)/K6*100 -> 2.1038429
C42: Consumo público | E42: 0.33825715 | F42: 0.26170613 | G42: 0.54807074 | H42: 0.43960632 | I42: -0.028941131 | J42: 0.39995952 | K42: 1.4120652 | L42: =(L9-K9)/K7*100 -> 2.4852259
C43: Formación bruta de capital fijo | D43: … | E43: -1.6682359 | F43: 4.6877461 | G43: -11.465161 | H43: 5.6904884 | I43: 4.9829921 | J43: 0.15649967 | K43: 0.97820981 | L43: =(L10-K10)/K6*100 -> 1.1575236
C44: Inversión privada | E44: 3.2428728 | F44: 1.5996554 | G44: -2.1510236 | H44: -0.25506575 | I44: 2.9659222 | J44: 0.12431123 | K44: 0.77701415 | L44: =(L11-K11)/K6*100 -> 0.91944716
C45: Inversión pública | E45: 0.24092332 | F45: 0.086288892 | G45: -0.28505942 | H45: 0.62441898 | I45: 0.48364079 | J45: 0.018088596 | K45: 0.11306376 | L45: =(L12-K12)/K6*100 -> 0.13378927
C46: Exportaciones de bienes y servicios | D46: … | E46: 5.1232476 | F46: -1.0751253 | G46: -3.0744683 | H46: 2.3967001 | I46: 3.401291 | J46: 4.239961 | K46: 1.8913308 | L46: =(L15-K15)/K6*100 -> 2.1756351
C47: Importaciones de bienes y servicios | D47: … | E47: -2.4119024 | F47: -3.6104405 | G47: 10.846683 | H47: -6.6266673 | I47: -6.2638732 | J47: -4.7786618 | K47: -2.6400501 | L47: =-(L16-K16)/K6*100 -> -3.0485597
...

Sheet Deflactor_PIB
C2: Macronia: Deflactor del PIB, 2006-12
D3: 2006 | E3: 2007 | F3: 2008 | G3: 2009 | H3: 2010 | I3: 2011 | J3: 2012 | K3: 2013 | L3: 2014 | P3: 2012 | Q3: 2013 | R3: 2014
D4: (en miles de millones de moneda nacional) | P4: (tasa de crecimiento anual, porcentaje)
C5: Producto interno bruto por gasto, a precios corrientes
C6: PIB | D6: 10964.62 | E6: 12956.322 | F6: 14737.186 | G6: 15747.009 | H6: 17629.078 | I6: 19427.849 | J6: 21157.293 | K6: 23646.186 | L6: =PIB_Nominal!L6 -> 26705.763 | P6: =J6/I6-1 -> 0.089018811 | Q6: =K6/J6-1 -> 0.11763758 | R6: =L6/K6-1 -> 0.12938988
C7: Consumo final | D7: 8700.4437 | E7: 10352.871 | F7: 12200.565 | G7: 13108.591 | H7: 14576.657 | I7: 16016.788 | J7: 17760.343 | K7: 19985.487 | L7: =PIB_Nominal!L7 -> 22689.509 | P7: =J7/I7-1 -> 0.10885793 | Q7: =K7/J7-1 -> 0.12528725 | R7: =L7/K7-1 -> 0.13529925
C8: Privado | D8: 7624.2096 | E8: 9087.1639 | F8: 10645.097 | G8: 11176.638 | H8: 12277.757 | I8: 13520.438 | J8: 15027.228 | K8: 16647.635 | L8: =PIB_Nominal!L8 -> 18389.33 | P8: =J8/I8-1 -> 0.11144535 | Q8: =K8/J8-1 -> 0.10783137 | R8: =L8/K8-1 -> 0.1046212
C9: Público | D9: 1076.2341 | E9: 1265.7069 | F9: 1555.4684 | G9: 1931.9535 | H9: 2298.9 | I9: 2496.35 | J9: 2733.1145 | K9: 3337.8524 | L9: =PIB_Nominal!L9 -> 4300.1784 | P9: =J9/I9-1 -> 0.094844277 | Q9: =K9/J9-1 -> 0.22126328 | R9: =L9/K9-1 -> 0.28830691
C10: Formación bruta de capital fijo | D10: 2919.2115 | E10: 3202.1678 | F10: 4044.0793 | G10: 2463.1898 | H10: 3463.1683 | I10: 4287.2834 | J10: 4493.8592 | K10: 4957.11 | L10: =PIB_Nominal!L10 -> 5598.6359 | P10: =J10/I10-1 -> 0.048183377 | Q10: =K10/J10-1 -> 0.10308528 | R10: =L10/K10-1 -> 0.12941532
C11: Privada | D11: 1935.5708 | E11: 2523.1836 | F11: 3083.0458 | G11: 3105.0591 | H11: 2992.8914 | I11: 3513.9263 | J11: 3683.2391 | K11: 4062.9269 | L11: =PIB_Nominal!L11 -> 4588.7319 | P11: =J11/I11-1 -> 0.048183377 | Q11: =K11/J11-1 -> 0.10308528 | R11: =L11/K11-1 -> 0.12941532
C12: Pública | D12: 234.02446 | E12: 286.08395 | F12: 335.24812 | G12: 328.85775 | H12: 425.53619 | I12: 510.29972 | J12: 534.88768 | K12: 590.02673 | L12: =PIB_Nominal!L12 -> 666.38523 | P12: =J12/I12-1 -> 0.048183377 | Q12: =K12/J12-1 -> 0.10308528 | R12: =L12/K12-1 -> 0.12941532
C13: Variación de saldos | D13: 749.61619 | E13: 392.90029 | F13: 625.78538 | G13: -970.72705 | H13: 44.740729 | I13: 263.05738 | J13: 275.73238 | K13: 304.15633 | L13: =PIB_Nominal!L13 -> 343.51882 | P13: =J13/I13-1 -> 0.048183377 | Q13: =K13/J13-1 -> 0.10308528 | R13: =L13/K13-1 -> 0.12941532
C14: Saldo externo | D14: -708.14401 | E14: -653.40526 | F14: -1531.9167 | G14: 98.335101 | H14: -432.6394 | I14: -937.22061 | J14: -1096.9087 | K14: -1296.4112 | L14: =PIB_Nominal!L14 -> -1582.3815 | P14: =J14/I14-1 -> 0.17038476 | Q14: =K14/J14-1 -> 0.18187697 | R14: =L14/K14-1 -> 0.22058612
C15: Exportaciones de bienes y servicios | D15: 5658.5976 | E15: 6623.9268 | F15: 7134.1258 | G15: 7122.0184 | H15: 7248.1128 | I15: 7780.1097 | J15: 8683.1333 | K15: 9484.6174 | L15: =PIB_Nominal!L15 -> 10660.409 | P15: =J15/I15-1 -> 0.11606823 | Q15: =K15/J15-1 -> 0.092303554 | R15: =L15/K15-1 -> 0.12396825
C16: Importaciones de bienes y servicios | D16: 6366.7416 | E16: 7277.3321 | F16: 8666.0425 | G16: 7023.6833 | H16: 7680.7522 | I16: 8717.3303 | J16: 9780.042 | K16: 10781.029 | L16: =PIB_Nominal!L16 -> 12242.79 | P16: =J16/I16-1 -> 0.12190793 | Q16: =K16/J16-1 -> 0.10234992 | R16: =L16/K16-1 -> 0.13558648
C17: Discrepancia estadística | D17: 53.108978 | E17: 54.688654 | F17: 24.458182 | G17: 76.893057 | H17: 21.891565 | I17: 60.998131 | J17: 0 | K17: 0 | L17: =PIB_Nominal!L17 -> 0
D19: (en miles de millones de moneda nacional)
C20: Producto interno bruto por gasto, a precios constantes de 2005
C21: PIB | D21: 9864.103 | E21: 10508.008 | F21: 10760.325 | G21: 10584.876 | H21: 11099.247 | I21: 11726.953 | J21: 12217.747 | K21: 12774.631 | L21: =PIB_real!L6 -> 13343.319 | P21: =J21/I21-1 -> 0.04185179 | Q21: =K21/J21-1 -> 0.04557993 | R21: =L21/K21-1 -> 0.044517021
C22: Consumo final | D22: 7726.1683 | E22: 8269.9833 | F22: 8549.1915 | G22: 8737.0493 | H22: 9135.1104 | I22: 9504.6399 | J22: 10043.482 | K22: 10605.631 | L22: =PIB_real!L7 -> 11137.963 | P22: =J22/I22-1 -> 0.056692565 | Q22: =K22/J22-1 -> 0.055971473 | R22: =L22/K22-1 -> 0.050193341
C23: Privado | D23: 6791.1229 | E23: 7301.5719 | F23: 7553.2801 | G23: 7682.1636 | H23: 8033.693 | I23: 8406.4347 | J23: 8898.374 | K23: 9288 | L23: =PIB_real!L8 -> 9556.7582 | P23: =J23/I23-1 -> 0.05851938 | Q23: =K23/J23-1 -> 0.043786197 | R23: =L23/K23-1 -> 0.028936064
C24: Público | D24: 935.04534 | E24: 968.41137 | F24: 995.91147 | G24: 1054.8857 | H24: 1101.4174 | I24: 1098.2052 | J24: 1145.1083 | K24: 1317.6308 | L24: =PIB_real!L9 -> 1581.2047 | P24: =J24/I24-1 -> 0.042708835 | Q24: =K24/J24-1 -> 0.15066047 | R24: =L24/K24-1 -> 0.20003622
C25: Formación bruta de capital fijo | D25: 2553.3827 | E25: 2388.8262 | F25: 2881.415 | G25: 1647.7264 | H25: 2250.0575 | I25: 2803.1322 | J25: 2821.4848 | K25: 2941 | L25: =PIB_real!L10 -> 3088.8694 | P25: =J25/I25-1 -> 0.0065471915 | Q25: =K25/J25-1 -> 0.042358972 | R25: =L25/K25-1 -> 0.050278602
C26: Privada | D26: 1667.8795 | E26: 1987.7598 | F26: 2155.8517 | G26: 1924.3946 | H26: 1897.3962 | I26: 2226.5912 | J26: 2241.1691 | K26: 2336.1027 | L26: =PIB_real!L11 -> 2453.5587 | P26: =J26/I26-1 -> 0.0065471915 | Q26: =K26/J26-1 -> 0.042358972 | R26: =L26/K26-1 -> 0.050278602
C27: Pública | D27: 202.05922 | E27: 225.82414 | F27: 234.89139 | G27: 204.21807 | H27: 270.31204 | I27: 323.99253 | J27: 326.11377 | K27: 339.92761 | L27: =PIB_real!L12 -> 357.0187 | P27: =J27/I27-1 -> 0.0065471915 | Q27: =K27/J27-1 -> 0.042358972 | R27: =L27/K27-1 -> 0.050278602
C28: Variación de saldos | D28: 683.44407 | E28: 175.24233 | F28: 490.6719 | G28: -480.8862 | H28: 82.349342 | I28: 252.54843 | J28: 254.20191 | K28: 264.96964 | L28: =PIB_real!L13 -> 278.29195 | P28: =J28/I28-1 -> 0.0065471915 | Q28: =K28/J28-1 -> 0.042358972 | R28: =L28/K28-1 -> 0.050278602
C29: Saldo externo | D29: -463.29412 | E29: -195.84423 | F29: -688.20384 | G29: 148.11167 | H29: -299.6251 | I29: -617.35019 | J29: -680.52337 | K29: -772 | L29: =PIB_real!L14 -> -883.51291 | P29: =J29/I29-1 -> 0.10232958
C30: Exportaciones de bienes y servicios | D30: 5101.933 | E30: 5607.2954 | F30: 5494.3211 | G30: 5163.4984 | H30: 5417.1861 | I30: 5794.7038 | J30: 6291.922 | K30: 6523 | L30: =PIB_real!L15 -> 6800.9293 | P30: =J30/I30-1 -> 0.085805633 | Q30: =K30/J30-1 -> 0.036726139 | R30: =L30/K30-1 -> 0.042607596
C31: Importaciones de bienes y servicios | D31: 5565.2271 | E31: 5803.1396 | F31: 6182.525 | G31: 5015.3867 | H31: 5716.8112 | I31: 6412.054 | J31: 6972.4454 | K31: 7295 | L31: =PIB_real!L16 -> 7684.4423 | P31: =J31/I31-1 -> 0.087396552 | Q31: =K31/J31-1 -> 0.046261335 | R31: =L31/K31-1 -> 0.053384819
C32: Discrepancia estadística | D32: 47.846148 | E32: 45.04249 | F32: 17.922271 | G32: 51.988291 | H32: 13.704398 | I32: 36.53094 | J32: 33.303032 | K32: 0 | L32: =PIB_real!L17 -> 0
C34: Deflactor del PIB
C35: PIB | D35: 111.15679 | E35: 123.29951 | F35: 136.95856 | G35: 148.76896 | H35: 158.83129 | I35: 165.66835 | J35: 173.16854 | K35: 185.1027 | L35: =L6/L21*100 -> 200.14333 | P35: =J35/I35-1 -> 0.045272294 | Q35: =K35/J35-1 -> 0.068916443 | R35: =L35/K35-1 -> 0.081255598
C36: Consumo final | D36: 112.61007 | E36: 125.18611 | F36: 142.71016 | G36: 150.03453 | H36: 159.56739 | I36: 168.51547 | J36: 176.83451 | K36: 188.44223 | L36: =L7/L22*100 -> 203.71327 | P36: =J36/I36-1 -> 0.049366647 | Q36: =K36/J36-1 -> 0.06564171 | R36: =L36/K36-1 -> 0.081038324
C37: Privado | D37: 112.26729 | E37: 124.4549 | F37: 140.93343 | G37: 145.48815 | H37: 152.82831 | I37: 160.83439 | J37: 168.87611 | K37: 179.2381 | L37: =L8/L23*100 -> 192.42226 | P37: =J37/I37-1 -> 0.05 | Q37: =K37/J37-1 -> 0.061358513 | R37: =L37/K37-1 -> 0.073556692
C38: Público | D38: 115.09967 | E38: 130.6993 | F38: 156.18541 | G38: 183.1434 | H38: 208.72195 | I38: 227.3118 | J38: 238.67739 | K38: 253.32228 | L38: =L9/L24*100 -> 271.95583 | P38: =J38/I38-1 -> 0.05 | Q38: =K38/J38-1 -> 0.061358513 | R38: =L38/K38-1 -> 0.073556692
C39: Formación bruta de capital fijo | D39: 114.32722 | E39: 134.04775 | F39: 140.35046 | G39: 149.49021 | H39: 153.91465 | I39: 152.94617 | J39: 159.27285 | K39: 168.55185 | L39: =L10/L25*100 -> 181.25195 | P39: =J39/I39-1 -> 0.041365359 | Q39: =K39/J39-1 -> 0.058258539 | R39: =L39/K39-1 -> 0.075348309
C40: Privada | D40: 116.0498 | E40: 126.93604 | F40: 143.00825 | G40: 161.35252 | H40: 157.73677 | I40: 157.81641 | J40: 164.34454 | K40: 173.91902 | L40: =L11/L26*100 -> 187.02352 | P40: =J40/I40-1 -> 0.041365359 | Q40: =K40/J40-1 -> 0.058258539 | R40: =L40/K40-1 -> 0.075348309
C41: Pública | D41: 115.81974 | E41: 126.6844 | F41: 142.72474 | G41: 161.03264 | H41: 157.42406 | I41: 157.50355 | J41: 164.01874 | K41: 173.57423 | L41: =L12/L27*100 -> 186.65275 | P41: =J41/I41-1 -> 0.041365359 | Q41: =K41/J41-1 -> 0.058258539 | R41: =L41/K41-1 -> 0.075348309
C42: Variación de saldos | D42: 109.68216 | E42: 224.20398 | F42: 127.53642 | G42: 201.86212 | H42: 54.330402 | I42: 104.16116 | J42: 108.46983 | K42: 114.78912 | L42: =L13/L28*100 -> 123.43829 | P42: =J42/I42-1 -> 0.041365359 | Q42: =K42/J42-1 -> 0.058258539 | R42: =L42/K42-1 -> 0.075348309
C43: Saldo externo | D43: … | E43: ... | F43: ... | G43: ... | H43: ... | I43: ... | J43: ... | K43: ... | L43: ...
...

Sheet BP
C2: Macronia: Balanza de pagos, 2006-13
D3: 2006 | E3: 2007 | F3: 2008 | G3: 2009 | H3: 2010 | I3: 2011 | J3: 2012 | K3: 2013 | L3: =1+K3 -> 2014
D4: (en millones dólares de EE.UU.)
C5: Cuenta corriente | D5: -1101.1511 | E5: -1372.9554 | F5: -2878.3333 | G5: -442.61129 | H5: -1302.5123 | I5: -2396.441 | J5: =J6+J9+J12+J17 -> -2724.3801 | K5: =K6+K9+K12+K17 -> -2959.8354 | L5: =L6+L9+L12+L17 -> -3329.4068
C6: Bienes | D6: -2727.1352 | E6: -2985.4503 | F6: -5013.3306 | G6: -2039.0602 | H6: -3439.6934 | I6: -5151.371 | J6: -5728.0786 | K6: -6194.2117 | L6: =L7-L8 -> -6755.0748
C7: Crédito | D7: 8101.7336 | E7: 9299.4773 | F7: 9555.3677 | G7: 8838.2254 | H7: 9516.2515 | I7: 10383.11 | J7: 11494.734 | K7: 12095.645 | L7: ='Import. y export. nominales'!M8 -> 12800.176
C8: Débito | D8: 10828.869 | E8: 12284.928 | F8: 14568.698 | G8: 10877.286 | H8: 12955.945 | I8: 15534.481 | J8: 17222.813 | K8: 18289.856 | L8: ='Import. y export. nominales'!M10 -> 19555.251
C9: Servicios | D9: 1351.0647 | E9: 1734.0675 | F9: 2200.9213 | G9: 2188.1006 | H9: 2537.2355 | I9: 3236.8748 | J9: 3580.602 | K9: 3749.1634 | L9: =L10-L11 -> 3945.1884
C10: Crédito | D10: 2971.6628 | E10: 3552.1823 | F10: 4083.3176 | G10: 3592.9105 | H10: 4319.9815 | I10: 4972.3539 | J10: 5504.6979 | K10: 5792.4672 | L10: =Servicios!I8 -> 6129.8593
C11: Débito | D11: 1620.5981 | E11: 1818.1148 | F11: 1882.3964 | G11: 1404.8099 | H11: 1782.7461 | I11: 1735.4792 | J11: 1924.0959 | K11: 2043.3038 | L11: =Servicios!I10 -> 2184.671
C12: Ingreso primario | D12: -74.180567 | E12: -591.2726 | F12: -508.22389 | G12: -950.4517 | H12: -766.5544 | I12: -804.8448 | J12: =J13-J15 -> -910.40435 | K12: =K13-K15 -> -857.69087 | L12: =L13-L15 -> -872.09248
C13: Crédito | D13: 705.91943 | E13: 703.4384 | F13: 617.81711 | G13: 253.4883 | H13: 316.8296 | I13: 272.3782 | J13: ='Ingreso primario'!G8 -> 173.86689 | K13: ='Ingreso primario'!H8 -> 184.98126 | L13: ='Ingreso primario'!I8 -> 170.57965
C14: del cual: renta de inversión | D14: 632.61943 | E14: 631.1384 | F14: 546.91711 | G14: 228.9883 | H14: 281.6296 | I14: 209.1782 | J14: ='Ingreso primario'!G9 -> 133.5245 | K14: ='Ingreso primario'!H9 -> 142.06 | L14: ='Ingreso primario'!I9 -> 131
C15: Débito | D15: 780.1 | E15: 1294.711 | F15: 1126.041 | G15: 1203.94 | H15: 1083.384 | I15: 1077.223 | J15: 1084.2712 | K15: 1042.6721 | L15: ='Ingreso primario'!H17 -> 1042.6721
C16: del cual: intereses | D16: 266.9 | E16: 438.2 | F16: 352.6 | G16: 308 | H16: 306.6 | I16: 284.1 | J16: 285.95886 | K16: 274.98777 | L16: ='Ingreso primario'!I18 -> 295.30314
C17: Ingreso secundario | D17: 349.1 | E17: 469.7 | F17: 442.3 | G17: 358.8 | H17: 366.5 | I17: 322.9 | J17: 333.50078 | K17: 342.90384 | L17: ='Ingreso secundario'!J6 -> 352.57201
C19: Cuenta de capital | D19: 1.1 | E19: 21.2 | F19: 7.4 | G19: 58.3 | H19: 53.6 | I19: 21.6 | J19: 37.513907 | K19: 9 | L19: 9
C21: Cuenta financiera: Préstamo neto (+)/endeudamiento neto (-) | D21: -1793.9 | E21: -2411.9 | F21: -2480.5 | G21: -676.9 | H21: -1800.2 | I21: -2518.9 | J21: -2684.7899 | K21: -2929.0456 | L21: =L22+L26+L33+L31 -> -3075.8603
C22: Inversión directa | D22: -1371 | E22: -1633.7 | F22: -2072.3 | G22: -1339 | H22: -1440.8 | I22: -2118.3 | J22: -1844.0043 | K22: -1985.4075 | L22: =(K22/K57)*L57 -> -2111.1857
C23: Adquisición neta de activos | D23: 98.1 | E23: 262.4 | F23: 5.9 | G23: 7.5 | H23: 24.8 | I23: 57.8 | J23: 505.44391 | K23: 544.20272 | L23: =K23/K$57*L$57 -> 578.67868
C24: Incurrimiento neto de pasivos | D24: 1469.1 | E24: 1896.1 | F24: 2078.2 | G24: 1346.5 | H24: 1465.6 | I24: 2176.1 | J24: 2349.4482 | K24: 2529.6102 | L24: =K24/K$57*L$57 -> 2689.8644
C26: Inversión de cartera | D26: 442.1 | E26: -11.6 | F26: -356.6 | G26: 276.1 | H26: -268.1 | I26: -261.4 | J26: -784.86019 | K26: -781.82486 | L26: =L27-L28 -> -792.61027
C27: Adquisición neta de activos | D27: 509.3 | E27: 170.4 | F27: -537.3 | G27: 321.7 | H27: -218.6 | I27: -258.9 | J27: 0 | K27: 0 | L27: 0
C28: Incurrimiento neto de pasivos | D28: 67.2 | E28: 182 | F28: -180.7 | G28: 45.6 | H28: 49.5 | I28: 2.5 | J28: 784.86019 | K28: 781.82486 | L28: =L29+L30 -> 792.61027
C29: Gobierno general | F29: -238.6 | G29: 101.7 | H29: 117.8 | I29: -207.7 | J29: 557.86019 | K29: 537.41788 | L29: =Gob_EOG!L47/'TC nominal'!I13*1000 -> 532.71979
C30: Otros (neto) | F30: 57.9 | G30: -56.1 | H30: -68.3 | I30: 210.2 | J30: 227 | K30: 244.40698 | L30: =(K30/K57)*L57 -> 259.89048
C31: Derivados financieros | D31: -25 | E31: 50 | F31: -19 | G31: 18 | H31: 78 | I31: 69 | J31: 74.496542 | K31: 80.209139 | L31: =K31/K$57*L$57 -> 85.290494
C33: Otra inversión | D33: -840 | E33: -816.6 | F33: -32.6 | G33: 368 | H33: -169.3 | I33: -208.2 | J33: -130.42202 | K33: -242.02236 | L33: =L34-L35 -> -257.35479
C34: Adquisición neta de activos | D34: -474.6 | E34: 155.8 | F34: 684.6 | G34: -332.2 | H34: 376.5 | I34: 214 | J34: 231.04725 | K34: 248.76457 | L34: =K34/K$57*L$57 -> 264.52414
C35: Incurrimiento neto de pasivos | D35: 365.4 | E35: 972.4 | F35: 717.2 | G35: -700.2 | H35: 545.8 | I35: 422.2 | J35: 455.83246 | K35: 490.78693 | L35: =K35/K$57*L$57 -> 521.87893
C36: del cual: otras sociedades de depósito | I36: 168.88 | J36: 182.33298 | K36: 294.47216 | L36: =0.4*L35 -> 208.75157
C37: del cual: gobierno general | D37: -52.9 | E37: -55.3 | F37: -43.2 | G37: -22.3 | H37: 477.6 | I37: 18.5 | J37: 0 | K37: 0 | L37: 0
C39: Errores y omisiones netos | D39: 56.951079 | E39: -42.444576 | F39: 42.433273 | G39: -32.688705 | H39: 9.8123142 | I39: -11.659001 | J39: 53.59964 | K39: 0 | L39: 0
C41: Saldo global | D41: 750.8 | E41: 1017.7 | F41: -348 | G41: 259.9 | H41: 561.1 | I41: 132.4 | J41: =J5+J19-J21+J39 -> 51.523344 | K41: =K5+K19-K21+K39 -> -21.789759 | L41: =L5+L19-L21+L39 -> -244.54656
C43: Activos de reserva (- = disminución) | D43: 750.8 | E43: 1017.7 | F43: -348 | G43: 259.9 | H43: 561.1 | I43: 132.4 | J43: =J41 -> 51.523344 | K43: =K41 -> -21.789759 | L43: =L41+L44 -> -244.54656
C44: Financiamiento del FMI
D45: (en porcentaje del PIB, salvo indicación en contrario)
C46: Indicadores económicos seleccionados | D46: 2006 | E46: 2007 | F46: 2008 | G46: 2009 | H46: 2010 | I46: 2011 | J46: 2012 | K46: 2013 | L46: =1+K46 -> 2014
C47: Saldo en cuenta corriente | D47: -5.1348842 | E47: -5.4744907 | F47: -10.277954 | G47: -1.6113773 | H47: -3.8850529 | I47: -6.2464852 | J47: =J5/J57*100 -> -6.5773304 | K47: =K5/K57*100 -> -6.6368464 | L47: =L5/L57*100 -> -7.0207629
C48: Saldo en cuenta de capital | D48: 0.0051295165 | E48: 0.08453239 | F48: 0.026423924 | G48: 0.21224785 | H48: 0.15987476 | I48: 0.056301858 | J48: 0.09056789 | K48: 0.021728236 | L48: =L19/$L$57*100 -> 0.018978415
...

Sheet PII
B2: Macronia: Posición de inversión internacional, 2006-2012
D3: 2006 | E3: 2007 | F3: 2008 | G3: 2009 | H3: 2010 | I3: 2011 | J3: 2012 | K3: 2013 | L3: 2014
B4: (en millones dólares de EE.UU.)
C5: Posición de inversión internacional neta | D5: -3563.8 | E5: -4969.8 | F5: -7774.2 | G5: -8174.6 | H5: -9410.3 | I5: -11800.6 | J5: -14565.561 | K5: =K7-K15 -> -17508.076 | L5: =L7-L15 -> -21093.007
C7: Activos | D7: 10162.9 | E7: 11795.4 | F7: 11617.7 | G7: 11915.2 | H7: 12732.4 | I7: 12928.9 | J7: =J8+J9+J10+J11+J13 -> 13775.632 | K7: =K8+K9+K10+K11+K13 -> 14633.787 | L7: =L8+L9+L10+L11+L13 -> 15053.21
C8: Inversiones directas en el exterior | D8: 1268 | E8: 1530.4 | F8: 1536.3 | G8: 1543.8 | H8: 1568.6 | I8: 1626.4 | J8: =I8+BP!J23 -> 2131.8439 | K8: =J8+BP!K23 -> 2676.0466 | L8: =K8+BP!L23 -> 3254.7253
C9: Inversiones de cartera | D9: 1317.9 | E9: 1488.2 | F9: 950.9 | G9: 1275.6 | H9: 1055 | I9: 796.1 | J9: 796.1 | K9: =J9+BP!K27 -> 796.1 | L9: =K9+BP!L27 -> 796.1
C10: Derivados financieros | D10: 351 | E10: 391 | F10: 379 | G10: 402 | H10: 472 | I10: 527 | J10: 568 | K10: =J10+BP!K31 -> 648.20914 | L10: =K10+BP!L31 -> 733.49963
C11: Otras inversiones | D11: 4111.4 | E11: 4272.2 | F11: 4952.8 | G11: 4627.6 | H11: 5007.1 | I11: 5221.1 | J11: 5469.8646 | K11: =J11+BP!L34 -> 5734.3887 | L11: =K11+BP!M34 -> 5734.3887
C12: de las cuales: dinero y depósitos de sociedades de depósito | D12: 656.69085 | E12: 523.13441 | F12: 1153.0422 | G12: 742.75689 | H12: 802.74399 | I12: 795.48962 | J12: … | K12: ... | L12: ...
C13: Activos de reserva | D13: 3114.6 | E13: 4113.6 | F13: 3798.7 | G13: 4066.2 | H13: 4629.7 | I13: 4758.3 | J13: =I13+BP!J43 -> 4809.8233 | K13: 4779.0428 | L13: =K13+BP!L43 -> 4534.4963
C15: Pasivos | D15: 13726.7 | E15: 16765.2 | F15: 19391.9 | G15: 20089.8 | H15: 22142.7 | I15: 24729.5 | J15: 28339.641 | K15: =K16+K19+K23+K24 -> 32141.863 | L15: =L16+L19+L23+L24 -> 36146.216
C16: Inversiones directas | D16: 6906.2 | E16: 8800.3 | F16: 10878.5 | G16: 12226 | H16: 13691.6 | I16: 15867.7 | J16: 18217.148 | K16: 20746.758 | L16: =K16+BP!L24 -> 23436.623
C17: Participaciones de capital y participaciones en fondos de inversión | D17: 6148.8 | E17: 8045.1 | F17: 10084.7 | G17: 11606.7 | H17: 12922.6 | I17: 14388 | J17: 16737.448 | K17: 19267.058 | L17: =L16-L18 -> 21956.923
C18: Títulos de deuda | D18: 757.4 | E18: 755.2 | F18: 793.8 | G18: 619.3 | H18: 769 | I18: 1479.7 | J18: 1479.7 | K18: 1479.7 | L18: =K18 -> 1479.7
C19: Inversiones de cartera | D19: 1177.4 | E19: 1359.4 | F19: 1183.7 | G19: 1229.3 | H19: 1278.8 | I19: 1281.3 | J19: 2066.1602 | K19: 2847.985 | L19: =K19+BP!L28 -> 3640.5953
C20: Participaciones de capital y participaciones en fondos de inversión | D20: 201 | E20: 213 | F20: 168 | G20: 178 | H20: 173 | I20: 171 | J20: 398 | K20: 642.40698 | L20: =L19-L21 -> 902.29746
C21: Títulos de deuda | D21: 976.4 | E21: 1146.4 | F21: 1015.7 | G21: 1051.3 | H21: 1105.8 | I21: 1110.3 | J21: 1668.1602 | K21: 2205.5781 | L21: =L22+(K21-K22) -> 2738.2979
C22: de los cuales: Bonos del gobierno general | D22: 966 | E22: 1122.1 | F22: 883.5 | G22: 985.2 | H22: 1103 | I22: 895.3 | J22: 1453.1602 | K22: 1990.5781 | L22: =K22+BP!L29 -> 2523.2979
C23: Derivados financieros | D23: 102 | E23: 92 | F23: 99 | G23: 104 | H23: 96 | I23: 82 | J23: 102 | K23: 102 | L23: =K23 -> 102
C24: Otras inversiones | D24: 5541.1 | E24: 6513.5 | F24: 7230.7 | G24: 6530.5 | H24: 7076.3 | I24: 7498.5 | J24: 7954.3325 | K24: 8445.1194 | L24: =K24+BP!L35 -> 8966.9983
C25: de las cuales: instrumentos de deuda | D25: 5512.2 | E25: 6464.6 | F25: 7154.8 | G25: 6208.2 | H25: 6757 | I25: 7174.2 | J25: 7088.2938 | K25: 7382.766 | L25: =SUM(L26:L29) -> 7591.5176
C26: Banco central | D26: 94 | E26: 88.9 | F26: 80.6 | G26: 58 | H26: 53.5 | I26: 303.8 | J26: 35.560839 | K26: 35.560839 | L26: =K26 -> 35.560839
C27: Otras sociedades de depósito | D27: 1160.1 | E27: 1693.8 | F27: 2400 | G27: 1582.6 | H27: 1616.3 | I27: 2337.4 | J27: 2519.733 | K27: 2814.2051 | L27: =K27+BP!L36 -> 3022.9567
C28: Gobierno general | D28: 564.5 | E28: 509.2 | F28: 466 | G28: 443.7 | H28: 921.3 | I28: 939.8 | J28: 939.8 | K28: 939.8 | L28: =K28 -> 939.8
C29: Otros sectores | D29: 3693.6 | E29: 4172.7 | F29: 4208.2 | G29: 4123.9 | H29: 4165.9 | I29: 3593.2 | J29: 3593.2 | K29: 3593.2 | L29: =K29 -> 3593.2
B31: (en porcentaje del PIB, salvo indicación en contrario)
C32: Indicadores de saldos
C33: Posición de inversión internacional neta | D33: -16.618701 | E33: -19.816466 | F33: -27.760117 | G33: -29.760571 | H33: -28.068459 | I33: -30.75906 | J33: -35.164882 | K33: -39.253025 | L33: =L5/L38*100 -> -44.479093
